<?xml version="1.0"?>
<sdf version="1.6">

    <model name='gen0_model'>
        <!-- Define robot links -->
        <link name="base_link">
            <pose>0 0 0 0 0 0</pose>
            <visual name='visual'>
                <pose>0 0 0 0 0 -1.57079633</pose>
                <geometry>
                    <mesh>
                        <uri>../meshes/gen0_colored.dae</uri>
                        <scale>1 1 1</scale>
                    </mesh>
                </geometry>
            </visual>
            <collision name='collision_base_link'>
                <pose>0 0 0 0 0 -1.57079633</pose>
                <geometry>
                    <mesh>
                        <uri>../meshes/gen0_colored.dae</uri>
                        <scale>1 1 1</scale>
                    </mesh>
                </geometry>
            </collision>
        </link>

        <link name="main_mass">
            <pose>0 0 0 0 0 0</pose>
            <inertial>
                <mass>1703.239</mass> <!-- Mass value is incorrect as the intertias are wrong-->
                <inertia>
                    <ixx>347.195805</ixx>
                    <ixy>-11.4914985</ixy>
                    <ixz>18.5070628</ixz>
                    <iyy>2330.10026</iyy>
                    <iyz>3.97814264</iyz>
                    <izz>2529.41827</izz>
                </inertia>
            </inertial>
        </link>

        <link name="back_right_steering_link">
            <pose>-1.4 -0.7925 0.33 0 0 0</pose>
            <inertial>
                <mass>50.00</mass>
                <inertia>
                    <ixx>0.25</ixx>
                    <ixy>0</ixy>
                    <ixz>0</ixz>
                    <iyy>0.1354</iyy>
                    <iyz>0</iyz>
                    <izz>0.1354</izz>
                </inertia>
            </inertial>
            <visual name='visual_back_right_steering'>
                <pose>0 0 0 1.570796 0 0</pose>
                <geometry>
                    <cylinder>
                        <length>0.05</length>
                        <radius>0.1</radius>
                    </cylinder>
                </geometry>
                <material>
                    <ambient>0.2 0.2 0.2 1</ambient>
                    <diffuse>0.2 0.2 0.2 1</diffuse>
                    <specular>0.2 0.2 0.2 1</specular>
                </material>
            </visual>
            <collision name='collision_back_right_steering'>
                <pose>0 0 0 1.570796 0 0</pose>
                <geometry>
                    <cylinder>
                        <length>0.05</length>
                        <radius>0.1</radius>
                    </cylinder>
                </geometry>
            </collision>
        </link>

        <link name="back_right_wheel_link">
            <pose>-1.4 -0.7925 0.33 0 0 -1.570796</pose>
            <inertial>
                <mass>20.00</mass>
                <inertia>
                    <ixx>1.089</ixx>
                    <ixy>0</ixy>
                    <ixz>0</ixz>
                    <iyy>0.5985</iyy>
                    <iyz>0</iyz>
                    <izz>0.5985</izz>
                </inertia>
            </inertial>
            <visual name='visual_back_right_wheel'>
                <geometry>
                    <mesh>
                        <uri>../meshes/gen0_wheels.dae</uri>
                        <scale>1 1 1</scale>
                    </mesh>
                </geometry>
            </visual>
            <collision name='collision_back_right_wheel'>
                <pose>0 0 0 0 1.570796 0</pose>
                <geometry>
                    <cylinder>
                        <length>0.18</length>
                        <radius>0.33</radius>
                    </cylinder>
                </geometry>
                <surface>
                    <friction>
                        <ode>
                            <mu>10000000</mu>
                            <mu2>7000</mu2>
                        </ode>
                    </friction>
                    <bounce>
                        <restitution_coefficient>0.0</restitution_coefficient>
                    </bounce>
                    <contact>
                        <ode>
                            <soft_cfm>0.001</soft_cfm>
                            <soft_erp>0.5</soft_erp>
                            <kp>10000000</kp>
                            <kd>1</kd>
                        </ode>
                    </contact>
                </surface>
            </collision>

        </link>

        <link name="back_left_steering_link">
            <pose>-1.4 0.7925 0.33 0 0 0</pose>
            <inertial>
                <mass>50.00</mass>
                <inertia>
                    <ixx>0.25</ixx>
                    <ixy>0</ixy>
                    <ixz>0</ixz>
                    <iyy>0.1354</iyy>
                    <iyz>0</iyz>
                    <izz>0.1354</izz>
                </inertia>
            </inertial>
            <visual name='visual_back_left_steering'>
                <pose>0 0 0 1.570796 0 0</pose>
                <geometry>
                    <cylinder>
                        <length>0.05</length>
                        <radius>0.1</radius>
                    </cylinder>
                </geometry>
                <material>
                    <ambient>0.2 0.2 0.2 1</ambient>
                    <diffuse>0.2 0.2 0.2 1</diffuse>
                    <specular>0.2 0.2 0.2 1</specular>
                </material>
            </visual>
            <collision name='collision_back_left_steering'>
                <pose>0 0 0 1.570796 0 0</pose>
                <geometry>
                    <cylinder>
                        <length>0.05</length>
                        <radius>0.1</radius>
                    </cylinder>
                </geometry>
            </collision>
        </link>

        <link name="back_left_wheel_link">
            <pose>-1.4 0.7925 0.33 0 0 1.570796</pose>
            <inertial>
                <mass>20.00</mass>
                <inertia>
                    <ixx>1.089</ixx>
                    <ixy>0</ixy>
                    <ixz>0</ixz>
                    <iyy>0.5985</iyy>
                    <iyz>0</iyz>
                    <izz>0.5985</izz>
                </inertia>
            </inertial>
            <visual name='visual_back_left_wheel'>
                <geometry>
                    <mesh>
                        <uri>../meshes/gen0_wheels.dae</uri>
                        <scale>1 1 1</scale>
                    </mesh>
                </geometry>
            </visual>
            <collision name='collision_back_left_wheel'>
                <pose>0 0 0 0 1.570796 0</pose>
                <geometry>
                    <cylinder>
                        <length>0.18</length>
                        <radius>0.33</radius>
                    </cylinder>
                </geometry>
                <surface>
                    <friction>
                        <ode>
                            <mu>10000000</mu>
                            <mu2>7000</mu2>
                        </ode>
                    </friction>
                    <bounce>
                        <restitution_coefficient>0.0</restitution_coefficient>
                    </bounce>
                    <contact>
                        <ode>
                            <soft_cfm>0.001</soft_cfm>
                            <soft_erp>0.5</soft_erp>
                            <kp>10000000</kp>
                            <kd>1</kd>
                        </ode>
                    </contact>
                </surface>
            </collision>
        </link>

        <link name="front_right_steering_link">
            <pose>1.4 -0.7925 0.33 0 0 0</pose>
            <inertial>
                <mass>50.00</mass>
                <inertia>
                    <ixx>0.25</ixx>
                    <ixy>0</ixy>
                    <ixz>0</ixz>
                    <iyy>0.1354</iyy>
                    <iyz>0</iyz>
                    <izz>0.1354</izz>
                </inertia>
            </inertial>
            <visual name='visual_front_right_steering'>
                <pose>0 0 0 1.570796 0 0</pose>
                <geometry>
                    <cylinder>
                        <length>0.05</length>
                        <radius>0.1</radius>
                    </cylinder>
                </geometry>
                <material>
                    <ambient>0.2 0.2 0.2 1</ambient>
                    <diffuse>0.2 0.2 0.2 1</diffuse>
                    <specular>0.2 0.2 0.2 1</specular>
                </material>
            </visual>
            <collision name='collision_front_right_steering'>
                <pose>0 0 0 1.570796 0 0</pose>
                <geometry>
                    <cylinder>
                        <length>0.05</length>
                        <radius>0.1</radius>
                    </cylinder>
                </geometry>
            </collision>
        </link>

        <link name="front_right_wheel_link">
            <pose>1.4 -0.7925 0.33 0 0 -1.570796</pose>
            <inertial>
                <mass>20.00</mass>
                <inertia>
                    <ixx>1.089</ixx>
                    <ixy>0</ixy>
                    <ixz>0</ixz>
                    <iyy>0.5985</iyy>
                    <iyz>0</iyz>
                    <izz>0.5985</izz>
                </inertia>
            </inertial>
            <visual name='visual_front_right_wheel'>
                <geometry>
                    <mesh>
                        <uri>../meshes/gen0_wheels.dae</uri>
                        <scale>1 1 1</scale>
                    </mesh>
                </geometry>
            </visual>
            <collision name='collision_front_right_wheel'>
                <pose>0 0 0 0 1.570796 0</pose>
                <geometry>
                    <cylinder>
                        <length>0.18</length>
                        <radius>0.33</radius>
                    </cylinder>
                </geometry>
                <surface>
                    <friction>
                        <ode>
                            <mu>10000000</mu>
                            <mu2>7000</mu2>
                        </ode>
                    </friction>
                    <bounce>
                        <restitution_coefficient>0.0</restitution_coefficient>
                    </bounce>
                    <contact>
                        <ode>
                            <soft_cfm>0.001</soft_cfm>
                            <soft_erp>0.5</soft_erp>
                            <kp>10000000</kp>
                            <kd>1</kd>
                        </ode>
                    </contact>
                </surface>
            </collision>
        </link>

        <link name="front_left_steering_link">
            <pose>1.4 0.7925 0.33 0 0 0</pose>
            <inertial>
                <mass>50.00</mass>
                <inertia>
                    <ixx>0.25</ixx>
                    <ixy>0</ixy>
                    <ixz>0</ixz>
                    <iyy>0.1354</iyy>
                    <iyz>0</iyz>
                    <izz>0.1354</izz>
                </inertia>
            </inertial>
            <visual name='visual_front_left_steering'>
                <pose>0 0 0 1.570796 0 0</pose>
                <geometry>
                    <cylinder>
                        <length>0.05</length>
                        <radius>0.1</radius>
                    </cylinder>
                </geometry>
                <material>
                    <ambient>0.2 0.2 0.2 1</ambient>
                    <diffuse>0.2 0.2 0.2 1</diffuse>
                    <specular>0.2 0.2 0.2 1</specular>
                </material>
            </visual>
            <collision name='collision_front_left_steering'>
                <pose>0 0 0 1.570796 0 0</pose>
                <geometry>
                    <cylinder>
                        <length>0.05</length>
                        <radius>0.1</radius>
                    </cylinder>
                </geometry>
            </collision>
        </link>

        <link name="front_left_wheel_link">
            <pose>1.4 0.7925 0.33 0 0 1.570796</pose>
            <inertial>
                <mass>20.00</mass>
                <inertia>
                    <ixx>1.089</ixx>
                    <ixy>0</ixy>
                    <ixz>0</ixz>
                    <iyy>0.5985</iyy>
                    <iyz>0</iyz>
                    <izz>0.5985</izz>
                </inertia>
            </inertial>
            <visual name='visual_front_left_wheel'>
                <geometry>
                    <mesh>
                        <uri>../meshes/gen0_wheels.dae</uri>
                        <scale>1 1 1</scale>
                    </mesh>
                </geometry>
            </visual>
            <collision name='collision_front_left_wheel'>
                <pose>0 0 0 0 1.570796 0</pose>
                <geometry>
                    <cylinder>
                        <length>0.18</length>
                        <radius>0.33</radius>
                    </cylinder>
                </geometry>
                <surface>
                    <friction>
                        <ode>
                            <mu>10000000</mu>
                            <mu2>7000</mu2>
                        </ode>
                    </friction>
                    <bounce>
                        <restitution_coefficient>0.0</restitution_coefficient>
                    </bounce>
                    <contact>
                        <ode>
                            <soft_cfm>0.001</soft_cfm>
                            <soft_erp>0.5</soft_erp>
                            <kp>10000000</kp>
                            <kd>1</kd>
                        </ode>
                    </contact>
                </surface>
            </collision>
        </link>
        <link name="front_3d_lidar_link">
            <pose>1.9 0 1.9 0 0 0</pose>
            <inertial>
                <mass>0.1</mass>
                <inertia>
                    <ixx>0.000166667</ixx>
                    <iyy>0.000166667</iyy>
                    <izz>0.000166667</izz>
                </inertia>
            </inertial>
            <collision name="lidar_collision">
                <geometry>
                    <box>
                        <size>0.1 0.1 0.1</size>
                    </box>
                </geometry>
            </collision>
            <visual name="lidar_visual">
                <geometry>
                    <box>
                        <size>0.1 0.1 0.1</size>
                    </box>
                </geometry>
            </visual>

            <sensor name='front_3d_gpu_lidar' type='gpu_lidar'>
                <pose>0 0 0 0 0 0</pose>
                <topic>front3d/scan</topic>
                <ignition_frame_id>front_3d_lidar_link</ignition_frame_id>
                <update_rate>10</update_rate>
                <lidar>
                    <scan>
                        <horizontal>
                            <samples>1024</samples>
                            <min_angle>-1.5707</min_angle>
                            <max_angle>1.5707</max_angle>
                        </horizontal>
                        <vertical>
                            <samples>64</samples>
                            <min_angle>-0.3926991</min_angle>
                            <max_angle>0.3926991</max_angle>
                        </vertical>
                    </scan>
                    <range>
                        <min>0.5</min>
                        <max>170</max>
                        <resolution>0.02</resolution>
                    </range>
                </lidar>
                <visualize>true</visualize>
            </sensor>
        </link>
        <link name="front_camera_link">
            <pose>1.9 0 1.6 0 0 0</pose>
            <inertial>
                <mass>0.1</mass>
                <inertia>
                    <ixx>0.000166667</ixx>
                    <iyy>0.000166667</iyy>
                    <izz>0.000166667</izz>
                </inertia>
            </inertial>
            <collision name="camera_collision">
                <geometry>
                    <box>
                        <size>0.1 0.1 0.1</size>
                    </box>
                </geometry>
            </collision>
            <visual name="camera_visual">
                <geometry>
                    <box>
                        <size>0.1 0.1 0.1</size>
                    </box>
                </geometry>
            </visual>

            <sensor name="front_camera" type="camera">
                <pose>0 0 0 0 0 0</pose>
                <topic>camera/images</topic>

                <camera>
                    <horizontal_fov>1.047</horizontal_fov>
                   
                    <image>
                        <width>900</width>
                        <height>700</height>
                        <format>R8G8B8</format>
                    </image>
                    <clip>
                        <near>0.1</near>
                        <far>100</far>
                    </clip>
                </camera>
                <update_rate>20</update_rate>
                 <always_on>1</always_on>
                <visualize>true</visualize>
                <!-- <plugin name="camera_controller" filename="libgazebo_ros_camera.so"> -->
                    <!-- <always_on>true</always_on>
                    <update_rate>30.0</update_rate>
                    <camera_name>front_camera</camera_name>
                    <image_topic_name>camera/image_raw</image_topic_name>
                    <camera_info_topic_name>camera/camera_info</camera_info_topic_name> -->
                    <!-- <frame_name>front_camera_joint</frame_name>
                </plugin> -->
            </sensor>
        </link>

        <link name="fr_2d_lidar_link">
            <pose>1.84 -0.85 0.33 0 0 0</pose>
            <inertial>
                <mass>0.1</mass>
                <inertia>
                    <ixx>0.000166667</ixx>
                    <iyy>0.000166667</iyy>
                    <izz>0.000166667</izz>
                </inertia>
            </inertial>
            <collision name="fr_2d_lidar_collision">
                <geometry>
                    <box>
                        <size>0.1 0.1 0.1</size>
                    </box>
                </geometry>
            </collision>
            <visual name="fr_2d_lidar_visual">
                <geometry>
                    <box>
                        <size>0.1 0.1 0.1</size>
                    </box>
                </geometry>
            </visual>

            <sensor name='fr_2d_gpu_lidar' type='gpu_lidar'>
                <pose>0 0 0 0 0 0</pose>
                <topic>fr/scan</topic>
                <ignition_frame_id>fr_2d_lidar_link</ignition_frame_id>
                <update_rate>20</update_rate>
                <lidar>
                    <scan>
                        <horizontal>
                            <samples>640</samples>
                            <min_angle>-2.356</min_angle>
                            <max_angle>1.5</max_angle>
                        </horizontal>
                        <vertical>
                            <samples>1</samples>
                            <min_angle>0.0</min_angle>
                            <max_angle>0.0</max_angle>
                        </vertical>
                    </scan>
                    <range>
                        <min>0.5</min>
                        <max>30</max>
                        <resolution>0.01</resolution>
                    </range>
                </lidar>
                <visualize>true</visualize>
            </sensor>
        </link>


        <link name="fl_2d_lidar_link">
            <pose>1.84 0.85 0.33 0 0 0</pose>
            <inertial>
                <mass>0.1</mass>
                <inertia>
                    <ixx>0.000166667</ixx>
                    <iyy>0.000166667</iyy>
                    <izz>0.000166667</izz>
                </inertia>
            </inertial>
            <collision name="fl_2d_lidar_collision">
                <geometry>
                    <box>
                        <size>0.1 0.1 0.1</size>
                    </box>
                </geometry>
            </collision>
            <visual name="fl_2d_lidar_visual">
                <geometry>
                    <box>
                        <size>0.1 0.1 0.1</size>
                    </box>
                </geometry>
            </visual>

            <sensor name='fl_2d_gpu_lidar' type='gpu_lidar'>
                <pose>0 0 0 0 0 0</pose>
                <topic>fl/scan</topic>
                <ignition_frame_id>fl_2d_lidar_link</ignition_frame_id>
                <update_rate>20</update_rate>
                <lidar>
                    <scan>
                        <horizontal>
                            <samples>640</samples>
                            <min_angle>-1.5</min_angle>
                            <max_angle>2.356</max_angle>
                        </horizontal>
                        <vertical>
                            <samples>1</samples>
                            <min_angle>0.0</min_angle>
                            <max_angle>0.0</max_angle>
                        </vertical>
                    </scan>
                    <range>
                        <min>0.5</min>
                        <max>30</max>
                        <resolution>0.01</resolution>
                    </range>
                </lidar>
                <visualize>true</visualize>
            </sensor>
        </link>


        <!-- <link name="imu_link">
            <pose>0.5 0 3 0 0 0</pose>
            <inertial>
                <mass>0.1</mass>
                <inertia>
                    <ixx>0.000166667</ixx>
                    <iyy>0.000166667</iyy>
                    <izz>0.000166667</izz>
                </inertia>
            </inertial>
            <collision name="imu_collision">
                <geometry>
                    <box>
                        <size>0.1 0.05 0.1</size>
                    </box>
                </geometry>
            </collision>
            <visual name="imu_visual">
                <geometry>
                    <box>
                        <size>0.1 0.05 0.1</size>
                    </box>
                </geometry>
            </visual>
            <sensor name='imu_sensor' type='imu'>
                <always_on>1</always_on>
                <update_rate>1</update_rate>
                <visualize>true</visualize>
                <topic>imu</topic>
            </sensor>
        </link> -->


        <joint name="inertial_joint" type="fixed">
            <parent>base_link</parent>
            <child>main_mass</child>
        </joint>

        <joint name='front_3d_lidar_joint' type='fixed'>
            <parent>base_link</parent>
            <child>front_3d_lidar_link</child>
        </joint>
        <joint name='front_camera_joint' type='fixed'>
            <parent>base_link</parent>
            <child>front_camera_link</child>
        </joint>
        

        <joint name='fr_2d_lidar_joint' type='fixed'>
            <parent>base_link</parent>
            <child>fr_2d_lidar_link</child>
        </joint>

        <joint name='fl_2d_lidar_joint' type='fixed'>
            <parent>base_link</parent>
            <child>fl_2d_lidar_link</child>
        </joint>


        <!-- 
    <joint name='lidar2_joint' type='fixed'>
        <parent>base_link</parent>
        <child>lidar2_link</child>
    </joint> -->

        <!-- <joint name='imu_joint' type='fixed'>
            <parent>base_link</parent>
            <child>imu_link</child>
        </joint> -->


        <joint name="back_right_steering_joint" type="revolute">
            <parent>base_link</parent>
            <child>back_right_steering_link</child>
            <axis>
                <xyz>0 0 1</xyz>
                <limit>
                    <lower>-0.5</lower>
                    <upper>0.5</upper>
                    <velocity>1000</velocity>
                    <effort>10000</effort>
                </limit>
            </axis>
        </joint>

        <joint name="back_right_wheel_joint" type="revolute">
            <parent>back_right_steering_link</parent>
            <child>back_right_wheel_link</child>
            <axis>
                <xyz>-1 0 0</xyz>
                <limit>
                    <lower>-1.79769e+308</lower>
                    <upper>1.79769e+308</upper>
                    <effort>10000</effort>
                    <velocity>5000</velocity>
                </limit>
            </axis>
            <dynamics>
                <damping>0.01</damping>
            </dynamics>
            <joint_properties>
                <damping>10</damping>
                <friction>1.0</friction>
            </joint_properties>
        </joint>

        <joint name="back_left_steering_joint" type="revolute">
            <parent>base_link</parent>
            <child>back_left_steering_link</child>
            <axis>
                <xyz>0 0 1</xyz>
                <limit>
                    <lower>-0.5</lower>
                    <upper>0.5</upper>
                    <velocity>1000</velocity>
                    <effort>10000</effort>
                </limit>
            </axis>
        </joint>

        <joint name="back_left_wheel_joint" type="revolute">
            <parent>back_left_steering_link</parent>
            <child>back_left_wheel_link</child>
            <axis>
                <xyz>1 0 0</xyz>
                <limit>
                    <lower>-1.79769e+308</lower>
                    <upper>1.79769e+308</upper>
                    <effort>10000</effort>
                    <velocity>5000</velocity>
                </limit>
            </axis>
            <dynamics>
                <damping>0.01</damping>
            </dynamics>
            <joint_properties>
                <damping>10</damping>
                <friction>1.0</friction>
            </joint_properties>
        </joint>

        <joint name="front_right_steering_joint" type="revolute">
            <parent>base_link</parent>
            <child>front_right_steering_link</child>
            <axis>
                <xyz>0 0 1</xyz>
                <limit>
                    <lower>-0.5</lower>
                    <upper>0.5</upper>
                    <velocity>1000</velocity>
                    <effort>10000</effort>
                </limit>
            </axis>
        </joint>

        <joint name="front_right_wheel_joint" type="revolute">
            <parent>front_right_steering_link</parent>
            <child>front_right_wheel_link</child>
            <axis>
                <xyz>-1 0 0</xyz>
                <limit>
                    <lower>-1.79769e+308</lower>
                    <upper>1.79769e+308</upper>
                    <effort>10000</effort>
                    <velocity>5000</velocity>
                </limit>
            </axis>
            <dynamics>
                <damping>0.01</damping>
            </dynamics>
            <joint_properties>
                <damping>10</damping>
                <friction>1.0</friction>
            </joint_properties>
        </joint>

        <joint name="front_left_steering_joint" type="revolute">
            <parent>base_link</parent>
            <child>front_left_steering_link</child>
            <axis>
                <xyz>0 0 1</xyz>
                <limit>
                    <lower>-0.5</lower>
                    <upper>0.5</upper>
                    <velocity>1000</velocity>
                    <effort>10000</effort>
                </limit>
            </axis>
        </joint>


        <joint name="front_left_wheel_joint" type="revolute">
            <parent>front_left_steering_link</parent>
            <child>front_left_wheel_link</child>
            <axis>
                <xyz>1 0 0</xyz>
                <limit>
                    <lower>-1.79769e+308</lower>
                    <upper>1.79769e+308</upper>
                    <effort>10000</effort>
                    <velocity>5000</velocity>
                </limit>
            </axis>
            <dynamics>
                <damping>0.01</damping>
            </dynamics>
            <joint_properties>
                <damping>10</damping>
                <friction>1.0</friction>
            </joint_properties>
        </joint>

        <!-- The ackermann plugin is only being used for speed control -->
        <plugin
            filename="ignition-gazebo-ackermann-steering-system"
            name="gz::sim::systems::AckermannSteering">
            <topic>/model/gen0_model/speed_cmd</topic>
            <odom_topic>ackodom</odom_topic>
            <left_joint>back_left_wheel_joint</left_joint>
            <right_joint>back_right_wheel_joint</right_joint>
            <left_steering_joint>back_left_steering_joint</left_steering_joint>
            <right_steering_joint>back_right_steering_joint</right_steering_joint>
            <kingpin_width>1.0</kingpin_width>
            <steering_limit>0.5</steering_limit>
            <wheel_base>2.8</wheel_base>
            <wheel_separation>1.385</wheel_separation>
            <wheel_radius>0.33</wheel_radius>
            <min_velocity>-3</min_velocity>
            <max_velocity>7</max_velocity>
            <min_acceleration>-6.25</min_acceleration> 
            <max_acceleration>3</max_acceleration>
        </plugin>

        <plugin
            filename="ignition-gazebo-joint-state-publisher-system"
            name="gz::sim::systems::JointStatePublisher">
        </plugin>

        <plugin
            filename="ignition-gazebo-joint-position-controller-system"
            name="gz::sim::systems::JointPositionController">
            <joint_name>front_left_steering_joint</joint_name>
            <topic>/model/gen0_model/joint/front_left_steering_joint/cmd_pos</topic>
            <use_velocity_commands>true</use_velocity_commands>
            <!-- <cmd_max>0.6</cmd_max>
            <cmd_min>-0.6</cmd_min> -->
        </plugin>

        <plugin
            filename="ignition-gazebo-joint-position-controller-system"
            name="gz::sim::systems::JointPositionController">
            <joint_name>front_right_steering_joint</joint_name>
            <topic>/model/gen0_model/joint/front_right_steering_joint/cmd_pos</topic>
            <use_velocity_commands>true</use_velocity_commands>
            <!-- <cmd_max>0.6</cmd_max>
            <cmd_min>-0.6</cmd_min> -->
        </plugin>

        <plugin
            filename="ignition-gazebo-pose-publisher-system"
            name="gz::sim::systems::PosePublisher">
            <publish_link_pose>true</publish_link_pose>
            <use_pose_vector_msg>true</use_pose_vector_msg>
            <publish_nested_model_pose>true</publish_nested_model_pose>
            <static_publisher>false</static_publisher>
        </plugin>

    </model>

</sdf>